Workbook

Sheet RESTAURANTESDESCUENTOS 2026
A1: 0 | B1: DESCUENTO | C1: RAZON SOCIAL | D1: ACTIVO | E1: PRODUCTO | F1: DOMICILIO | G1: OBSERVACIONES | H1: MARCACION | I1: CRÉDITO | J1: DIRECCION
A2: HIJO DE TIGRE | B2: 0.25 | C2: BODEGA LEOPARDO | D2: ACTIVO | E2: GRANDE ORIGINAL - R | F2: LUNES Y JUEVES N/A OTRO DÍA $10.000 | H2: X10 | I2: 15 DÍAS | J2: COMPLEX LOS BALSOS Cra. 25 #12 Sur-59, El Poblado
A3: ENTRECOTE BY CATA INTERPLAZA | B3: 0.25 | C3: CATALINA FERNANDEZ SAS | D3: ACTIVO | E3: GRANDE ORIGINAL - R | F3: 10000 | H3: X10 | I3: 8 DÍAS | J3: INTERPLAZA Cra. 30 #10C-228, El Poblado
A4: ENTRECOTE BY CATA INDIANA | B4: 0.25 | C4: CATALINA FERNANDEZ SAS | D4: ACTIVO | E4: GRANDE ORIGINAL - R | F4: 15000 | H4: X10 | I4: 8 DÍAS | J4: INDIANA MALL #Local 121, Las Palmas
A5: ENTRECOTE BY CATA RETIRO | B5: 0.25 | C5: CATALINA FERNANDEZ SAS | D5: ACTIVO | E5: GRANDE ORIGINAL - R | F5: 25000 | H5: X10 | I5: 8 DÍAS | J5: Cra. 20 #19-30, Retiro, Antioquia
A6: LA ABUELA NITA | B6: 0.25 | C6: ENSORE SAS | D6: ACTIVO | E6: GRANDE ORIGINAL - R | F6: N/A | H6: X12 | I6: 8 DÍAS | J6: Mall Punto de Encuentro
A7: ERNESTO SALON COMEDOR | B7: 0.25 | C7: SIMON RESTREPO CALLE | D7: ACTIVO | E7: GRANDE ORIGINAL - R | F7: 25000 | H7: X10 | I7: 8 DÍAS | J7: Sector el altico, Cra. 20 #23-39, Retiro, Antioquia
A8: AMMAZZA LAURELES | B8: 0.25 | C8: AMMAZZA LAURELES SAS | D8: NO | E8: MEDIANA ORIGINAL - R | F8: N/A | H8: X10 | I8: 8 DÍAS | J8: Cra. 76 #73b - 39, Laureles - Estadio
A9: AMMAZZA INDIANA | B9: 0.25 | C9: AMMAZZA INDIANA SAS | D9: NO | E9: MEDIANA ORIGINAL - R | F9: N/A | H9: X10 | I9: 8 DÍAS | J9: INDIANA MALL #Local 121, Las Palmas
A10: AMMAZZA AMSTERDAM | B10: 0.25 | C10: AMMAZZA AMSTERDAM SAS | D10: NO | E10: MEDIANA ORIGINAL - R | F10: N/A | H10: X10 | I10: 8 DÍAS | J10: AMSTERDAM PLAZA Cra. 25 #4-165, El Poblado
A11: BARBARO POBLADO | B11: 0.25 | C11: BARBARO POBLADO SAS | D11: NO | E11: MEDIANA ORIGINAL - R | F11: N/A | H11: X10 | I11: 8 DÍAS | J11: Cra. 37 #10a-23, El Poblado
A12: BARBARO LAURELES | B12: 0.25 | C12: BARBARO LAURELES SAS | D12: NO | E12: MEDIANA ORIGINAL - R | F12: N/A | H12: X10 | I12: 8 DÍAS | J12: Cra. 76 #73b-39, Laureles - Estadio
A13: BARBARO RIONEGRO | B13: 0.25 | C13: BARBARO RIONEGRO SAS | D13: NO | E13: MEDIANA ORIGINAL - R | F13: N/A | H13: X10 | I13: 8 DÍAS | J13: Rionegro, Antioquia
A14: BARBARO VIVA ENVIGADO | B14: 0.25 | C14: BARBARO VIVA ENVIGADO SAS | D14: NO | E14: MEDIANA ORIGINAL - R | F14: N/A | H14: X10 | I14: 8 DÍAS | J14: Cra. 48 #32B Sur-139
A15: CASA DE NADIE | B15: 0.25 | C15: INVERSIONES ENTRE PINOS SAS | D15: ACTIVO | E15: GRANDE ORIGINAL - R | F15: 10000 | G15: Tambien piden bites originales y les quedan en 4.000 | H15: X12 | I15: 8 DÍAS | J15: Loma los balsos, Casaloma, Medellín
A16: GRILL STATION POBLADO | B16: 0.25 | C16: FAIPA FRANQUICIAS SAS | D16: ACTIVO | E16: GRANDE ORIGINAL - R | F16: N/A | G16: SE FACTURA AREQUIPE-200 CANTIDAD- $110 VALOR UNITARIO | H16: X10 | I16: 8 DÍAS | J16: PROVENZA Cra. 34 #7-90, El Poblado
A17: GRILL STATION LAURELES | B17: 0.25 | C17: FAIPA FRANQUICIAS SAS | D17: ACTIVO | E17: GRANDE ORIGINAL - R | F17: N/A | G17: SE FACTURA AREQUIPE-200 CANTIDAD- $110 VALOR UNITARIO | H17: X10 | I17: 8 DÍAS | J17: Cq. 76 #73B-17, Laureles - Estadio
A18: GRILL STATION COLORES | B18: 0.25 | C18: FAIPA FRANQUICIAS SAS | D18: ACTIVO | E18: GRANDE ORIGINAL - R | F18: N/A | G18: SE FACTURA AREQUIPE-200 CANTIDAD- $110 VALOR UNITARIO | H18: X10 | I18: 8 DÍAS | J18: MALL LOS COLORES Cl. 53 #72-44, Laureles - Estadio, Medellín
A19: GRILL STATION LLANOGRANDE | B19: 0.25 | C19: FAIPA FRANQUICIAS SAS | D19: ACTIVO | E19: GRANDE ORIGINAL - R | F19: N/A | G19: SE FACTURA AREQUIPE-200 CANTIDAD- $110 VALOR UNITARIO | H19: X10 | I19: 8 DÍAS | J19: Mall Jardines de Llanogrande
A20: GRILL STATION SAN LUCAS | B20: 0.25 | C20: FAIPA FRANQUICIAS SAS | D20: ACTIVO | E20: GRANDE ORIGINAL - R | F20: N/A | G20: SE FACTURA AREQUIPE-200 CANTIDAD- $110 VALOR UNITARIO | H20: X10 | I20: 8 DÍAS | J20: San Lucas Plaza, Cl. 20 Sur #27-55 Of. 9980
A21: GRILL STATION ENVIGADO | B21: 0.25 | C21: FAIPA FRANQUICIAS SAS | D21: ACTIVO | E21: GRANDE ORIGINAL - R | F21: N/A | G21: SE FACTURA AREQUIPE-200 CANTIDAD- $110 VALOR UNITARIO | H21: X10 | I21: 8 DÍAS | J21: Calle 36d sur # 27a-105, LOCAL 350
A22: AZUL SELVA | B22: 0.25 | C22: GRUPO AS SAS | D22: ACTIVO | E22: GRANDE ORIGINAL - R | F22: N/A | G22: PAGA TODOS LOS 30 DEL MES | H22: X12 | I22: 30 DÍAS | J22: VIA PRIMAVERA Cra. 37 #8a-60, El Poblado
A23: EL CAFE CHALET | B23: 0.25 | C23: HAROLD RAMOS VARGAS | D23: ACTIVO | E23: GRANDE ORIGINAL - R | F23: N/A | H23: X12 | I23: 8 DÍAS
A24: MIENTRAS TIN TO | B24: 0.25 | C24: JOHAN ALEJANDRO RAMIREZ GIRALDO | D24: ACTIVO | E24: GRANDE ORIGINAL - R | F24: N/A | H24: X10 | I24: 8 DÍAS
A25: SANTIAGO FARLEY COCINA | B25: 0.25 | C25: SANTIAGO FARLEY CASTAÑO | D25: ACTIVO | E25: VARIEDAD | F25: DEPENDE DEL LUGAR (ANDRES NOS DICE) | I25: 8 DÍAS
A26: SHIBUYA | B26: 0.25 | C26: TORRES SANTIAGO OCAMPO | D26: ACTIVO | E26: MEDIANA ORIGINAL - R | F26: N/A | H26: X10 | I26: 8 DÍAS | J26: INDIANA MALL #Local 121, Las Palmas
A27: LA FRAGUA | B27: 0.25 | C27: CON CARITA DE NADA SAS | D27: ACTIVO | E27: MEDIANA ORIGINAL - R | F27: 10000 | G27: TAMBIEN PIDE GRANDE X12 | H27: X10 | I27: 8 DÍAS | J27: Escuela De Equitacion EQUUS Zuniga Parte Alta
A28: MERO | B28: 0.3 | C28: MERO SAS 901.444.356-0 | D28: ACTIVO | E28: GRANDE ORIGINAL - R | F28: 5000 | G28: SE FACTURA FRUTOS ROJOS-150 CANTIDAD- $110 VALOR UNITARIO | H28: X10 | I28: 8 DÍAS | J28: MALL ZONA 2 Cra. 32 #2 Sur 47, El Poblado
A29: ENSO | B29: 0.3 | C29: CORANTE SAS | D29: ACTIVO | E29: GRANDE ORIGINAL - R | F29: 5000 | H29: X10 | I29: 8 DÍAS | J29: Carrera 36 #8a39 Poblado
A30: GENERAL CAFE | B30: 0.3 | C30: GENERAL CAFE Y BAR SAS | D30: ACTIVO | E30: GRANDE ORIGINAL - R | F30: 5000 | G30: Horario de recepcion 7am-6pm | H30: X10 | I30: 8 DÍAS | J30: Cl. 13 #43D-84 Local 101, 102, El Poblado
A31: CASA FLORA | B31: 0.3 | C31: BOHEMIAN FLOWERS S.A.S | D31: ACTIVO | E31: GRANDE ORIGINAL - R | F31: 10000 | H31: X12 | I31: 15 DÍAS | J31: Cruce EL TABLAZO, via Rionegro
A32: AMBIENTE LIVING | B32: 0.3525 | C32: LIVING RESTAURANTES | D32: ACTIVO | E32: GRANDE ORIGINAL - R | F32: 8000 | H32: X10 | I32: 8 DÍAS | J32: TESORO CENTRO COMERCIAL
A33: VELEZ CAFE EL TESORO | C33: CAFE ARTISAN SAS | D33: ACTIVO | E33: MINI ORIGINAL - VELEZ CAFE | G33: SOLO SE DESPACHA MIERCOLES Y VIERNES Horario permitido entregas: 9:00am – 11:00 am | I33: 30 DÍAS | J33: TESORO CENTRO COMERCIAL PISO 2
A34: VELEZ CAFE EL TESORO | C34: CAFE ARTISAN SAS | D34: ACTIVO | E34: MINI PISTACHO - VELEZ CAFE | F34: N/A | G34: SOLO SE DESPACHA MIERCOLES Y VIERNES Horario permitido entregas: 9:00am – 11:00 am | I34: 30 DÍAS
A35: VELEZ CAFE EL TESORO | C35: CAFE ARTISAN SAS | D35: ACTIVO | E35: MINI MILO - VELEZ CAFE | G35: SOLO SE DESPACHA MIERCOLES Y VIERNES Horario permitido entregas: 9:00am – 11:00 am | I35: 30 DÍAS
A36: VELEZ CAFE SANTAFE | C36: CAFE ARTISAN SAS | D36: ACTIVO | E36: MINI ORIGINAL - VELEZ CAFE | G36: SOLO SE DESPACHA MIERCOLES Y VIERNES Horario permitido entregas: 8:00am – 11:00 am | I36: 30 DÍAS | J36: CC SANTAFE PISO 2
A37: VELEZ CAFE SANTAFE | C37: CAFE ARTISAN SAS | D37: ACTIVO | E37: MINI PISTACHO - VELEZ CAFE | F37: N/A | G37: SOLO SE DESPACHA MIERCOLES Y VIERNES Horario permitido entregas: 8:00am – 11:00 am | I37: 30 DÍAS
A38: VELEZ CAFE SANTAFE | C38: CAFE ARTISAN SAS | D38: ACTIVO | E38: MINI MILO - VELEZ CAFE | G38: SOLO SE DESPACHA MIERCOLES Y VIERNES Horario permitido entregas: 8:00am – 11:00 am | I38: 30 DÍAS
A39: VELEZ CAFE CALI | C39: CAFE ARTISAN SAS | D39: ACTIVO | E39: MINI ORIGINAL - VELEZ CAFE | G39: RECIBEN DE 9AM A 11 AM TOCA ENVIAR CON TRANSPORTADORA HACIA CALI Nevera M: caben 108 mini tartas Nevera XM: caben 204 mini tartas | I39: 30 DÍAS | J39: Calle 3 # 52 - 253, Cuarto de Legua #52-253, Cali - Mallplaza
A40: VELEZ CAFE CALI | C40: CAFE ARTISAN SAS | D40: ACTIVO | E40: MINI PISTACHO - VELEZ CAFE | G40: RECIBEN DE 9AM A 11 AM TOCA ENVIAR CON TRANSPORTADORA HACIA CALI Nevera M: caben 108 mini tartas Nevera XM: caben 204 mini tartas | I40: 30 DÍAS
...

Sheet INVENTARIO DIARIO PT
A1: FECHA | B1: CANTIDAD | C1: PRODUCTO | D1: COMENTARIOS | E1: REVISADO
A2: 46062 | B2: 3 | C2: PORCION OG | E2: DANIELA
A3: 46062 | B3: 16 | C3: MINI OG | E3: DANIELA
A4: 46062 | B4: 16 | C4: MEDIANA OG | E4: DANIELA
A5: 46062 | B5: 15 | C5: GRANDE OG | E5: DANIELA
A6: 46062 | B6: 6 | C6: MINI ORIGINAL X COOKIE WORLD | E6: DANIELA
A7: 46062 | B7: 5 | C7: MEDIANA ORIGINAL X COOKIE WORLD | E7: DANIELA
A8: 46062 | B8: 1 | C8: MEDIANA PISTACHO | E8: DANIELA
A9: 46062 | B9: 1 | C9: BITES X4 OG | E9: DANIELA
A10: 46062 | B10: 21 | C10: MINI ORIGINAL VELEZ CAFE | E10: DANIELA
A11: 46062 | B11: 9 | C11: MINI PISTACHO VELEZ CAFE | E11: DANIELA
A12: 46062 | B12: 6 | C12: MINI MILO CAFE VELEZ CAFE | E12: DANIELA
A13: 46063 | B13: 10 | C13: PORCION OG | E13: DANIELA
... A229: 46090 | B229: 10 | C229: MINI MILO CAFE VELEZ CAFE | E229: DANIELA
A230: 46091 | B230: 12 | C230: GRANDE OG | D230: 2 Grandes factura doble la abuela nita | E230: DANIELA
A231: 46091 | B231: 20 | C231: MEDIANA OG | E231: DANIELA
A232: 46091 | B232: 8 | C232: MINI OG | E232: DANIELA
A233: 46091 | B233: 6 | C233: MINI LOTUS | E233: DANIELA
A234: 46091 | B234: 3 | C234: MINI VAINILLA | E234: DANIELA
A235: 46091 | B235: 1 | C235: MINI MILO | E235: DANIELA
A236: 46091 | B236: 5 | C236: BITES X4 OG | E236: DANIELA
A237: 46091 | B237: 3 | C237: PORCION OG | E237: DANIELA
A238: 46091 | B238: 1 | C238: MINI PISTACHO | E238: DANIELA
A239: 46092 | B239: 19 | C239: GRANDE OG | E239: DANIELA
A240: 46092 | B240: 15 | C240: MEDIANA OG | E240: DANIELA
A241: 46092 | B241: 17 | C241: MINI OG | E241: DANIELA
A242: 46092 | B242: 4 | C242: MINI PISTACHO | E242: DANIELA
... A355: 46105 | B355: 10 | C355: MINI OG | E355: DANIELA
A356: 46105 | B356: 7 | C356: PORCION OG | D356: 2 MAS, PEDIDO CANCELADO DE RAPPI | E356: DANIELA
A357: 46105 | B357: 1 | C357: GRANDE VAINILLA | E357: DANIELA
A358: 46105 | B358: 1 | C358: MEDIANA PISTACHO | E358: DANIELA
A359: 46105 | B359: 2 | C359: MEDIANA LOTUS | E359: DANIELA
A360: 46105 | B360: 2 | C360: MEDIANA VAINILLA | E360: DANIELA
A361: 46105 | B361: 4 | C361: MINI LOTUS | E361: DANIELA
A362: 46105 | B362: 1 | C362: MINI VAINILLA | E362: DANIELA
A363: 46105 | B363: 4 | C363: MINI PISTACHO | E363: DANIELA
A364: 46105 | B364: 7 | C364: BITES X4 OG | E364: DANIELA
A365: 46106 | B365: 29 | C365: GRANDE OG | E365: DANIELA
A366: 46106 | B366: 25 | C366: MEDIANA OG | E366: DANIELA
A367: 46106 | B367: 19 | C367: MINI OG | E367: DANIELA
...

Sheet PRODUCCION
A1: FECHA | B1: CANTIDAD | C1: PRODUCTO | D1: COMENTARIOS | E1: INGRESADO
A2: 46025 | B2: 20 | C2: GRANDE OG | E2: OK
A3: 46025 | B3: 10 | C3: MINI OG | E3: OK
A4: 46025 | B4: 2 | C4: MEDIANA LOTUS | E4: OK
A5: 46025 | B5: 12 | C5: PORCION OG | D5: SE PORCIONA 1 GRANDE X12 | E5: OK
A6: 46027 | B6: 20 | C6: MEDIANA OG | E6: OK
A7: 46027 | B7: 10 | C7: MINI OG | E7: OK
A8: 46028 | B8: 15 | C8: MEDIANA OG | E8: OK
A9: 46028 | B9: 15 | C9: MINI OG | E9: OK
A10: 46028 | B10: 3 | C10: BITES X4 OG | E10: OK
A11: 46028 | B11: 79 | C11: MASA GALLETA DE BITES | E11: OK
A12: 46029 | B12: 15 | C12: GRANDE OG | E12: OK
A13: 46029 | B13: 10 | C13: MEDIANA OG | E13: OK
A14: 46029 | B14: 12 | C14: PORCION OG | D14: SE PORCIONA 1 GRANDE X12 | E14: OK
A15: 46030 | B15: 2 | C15: BITES X4 OG | E15: OK
A16: 46030 | B16: 15 | C16: GRANDE OG | E16: OK
A17: 46030 | B17: 15 | C17: MINI OG | E17: OK
A18: 46030 | B18: 1 | C18: MEDIANA LOTUS | E18: OK
A19: 46032 | B19: 3 | C19: BITES X4 OG | E19: OK
A20: 46032 | B20: 10 | C20: MINI OG | E20: OK
A21: 46032 | B21: 10 | C21: MEDIANA OG | E21: OK
A22: 46032 | B22: 10 | C22: GRANDE OG | E22: OK
A23: 46031 | B23: 1 | C23: MEDIANA VAINILLA | E23: OK
A24: 46035 | B24: 21 | C24: MEDIANA OG | E24: OK
A25: 46035 | B25: 5 | C25: GRANDE OG | E25: OK
A26: 46035 | B26: 10 | C26: MINI OG | E26: OK
... A36: 46037 | B36: 2 | C36: MINI PISTACHO | E36: OK
A37: 46037 | B37: 12 | C37: PORCION OG | D37: SE PORCIONA 1 GRANDE X12 | E37: OK
A38: 46037 | B38: 1 | C38: GRANDE LIMON | E38: OK
A39: 46038 | B39: 4 | C39: BITES X4 NUTELLA | D39: INDIVIDUALES / NUTELLA | E39: OK
A40: 46038 | B40: 4 | C40: BITES X4 VAINILLA MADAGASCAR | D40: INDIVIDUALES / VAINILLA | E40: OK
A41: 46038 | B41: 4 | C41: BITES X4 OG | D41: INDIVIDUALES / ORIGINAL | E41: OK
A42: 46038 | B42: 4 | C42: BITES X4 PISTACHO | D42: INDIVIDUALES / PISTACHOS | E42: OK
A43: 46038 | B43: 4 | C43: BITES X4 LOTUS | D43: INDIVIDUALES / LOTUS | E43: OK
A44: 46038 | B44: 4 | C44: BITES X4 OG | D44: INDIVIDUALES / ORIGINAL + AREQUIPE | E44: OK
A45: 46038 | B45: 1 | C45: GALLETA CHIPS CHOCOLATE X35 | E45: OK
A46: 46038 | B46: 1 | C46: GALLETA CHIPS CHOCOLATE BLANCO X35 | E46: OK
A47: 46038 | B47: 1 | C47: GRANDE VAINILLA | E47: OK
A48: 46038 | B48: 1 | C48: MEDIANA LOTUS | E48: OK
A49: 46039 | B49: 10 | C49: MINI OG | E49: OK
...

Sheet TRASLADOS BODEGAS
A1: FECHA | B1: CANTIDAD | C1: PRODUCTO | D1: COMENTARIOS | E1: INGRESADO
A2: 46010 | B2: 4 | C2: MEDIANA OG | E2: OK
A3: 46010 | B3: 5 | C3: GRANDE OG | D3: 2 CAJA BLANCA X12 | E3: OK
A4: 46011 | B4: 4 | C4: GRANDE OG | D4: MARCADA X12 | E4: OK
A5: 46015 | B5: 5 | C5: GRANDE OG | D5: MARCADA X12 | E5: OK
A6: 46015 | B6: 3 | C6: GRANDE NAVIDAD | E6: OK
A7: 46014 | B7: 6 | C7: MINI OG | E7: OK
A8: 46014 | B8: 4 | C8: MINI NAVIDAD | E8: OK
A9: 46016 | B9: 4 | C9: GRANDE OG | D9: MARCADA X12 | E9: OK
A10: 46016 | B10: 2 | C10: MEDIANA OG | E10: OK
A11: 46016 | B11: 2 | C11: MEDIANA NAVIDAD | E11: OK
A12: 46016 | B12: 2 | C12: MINI OG | E12: OK
A13: 46016 | B13: 4 | C13: MINI NAVIDAD | E13: OK
A14: 46018 | B14: 4 | C14: MINI OG | E14: OK
A15: 46018 | B15: 4 | C15: MINI NAVIDAD | E15: OK
A16: 46018 | B16: 4 | C16: MEDIANA OG | E16: OK
A17: 46018 | B17: 4 | C17: MEDIANA NAVIDAD | E17: OK
A18: 46018 | B18: 4 | C18: GRANDE OG | D18: MARCADA X12 CAJA BLANCA | E18: OK
A19: 46020 | B19: 5 | C19: MINI OG | E19: OK
A20: 46020 | B20: 10 | C20: GRANDE OG | D20: MARCADA X12 | E20: OK
A21: 46021 | B21: 6 | C21: GRANDE OG | D21: MARCADA X12 3 SE PORCIONAN | E21: OK
A22: 46021 | B22: 7 | C22: MEDIANA OG | E22: OK
A23: 46024 | B23: 6 | C23: MINI OG | E23: OK
A24: 46024 | B24: 6 | C24: MEDIANA OG | E24: OK
A25: 46024 | B25: 3 | C25: GRANDE OG | D25: MARCADA X12 | E25: OK
A26: 46025 | B26: 10 | C26: GRANDE OG | D26: MARCADA X12 | E26: OK
A27: 46025 | B27: 5 | C27: MINI OG | E27: OK
A28: 46029 | B28: 6 | C28: GRANDE OG | D28: x12 / 3 EN CAJA BLANCA | E28: OK
A29: 46029 | B29: 4 | C29: MEDIANA OG | E29: OK
A30: 46029 | B30: 3 | C30: MEDIANA NAVIDAD | E30: OK
A31: 46029 | B31: 2 | C31: MINI OG | E31: OK
A32: 46029 | B32: 3 | C32: MINI NAVIDAD | E32: OK
A33: 46031 | B33: 4 | C33: MEDIANA NAVIDAD | E33: OK
A34: 46031 | B34: 2 | C34: MEDIANA OG | E34: OK
A35: 46031 | B35: 6 | C35: GRANDE OG | D35: MARCADA X12 | E35: OK
A36: 46037 | B36: 4 | C36: GRANDE OG | D36: MARCADA X12 | E36: OK
A37: 46037 | B37: 4 | C37: MEDIANA OG | E37: OK
A38: 46037 | B38: 6 | C38: MINI OG | E38: OK
A39: 46039 | B39: 4 | C39: MINI OG | E39: OK
A40: 46039 | B40: 8 | C40: GRANDE OG | D40: MARCADA X12 | E40: OK
...

Sheet PEDIDOS
A1: CLIENTE | B1: FECHA DE ENTREGA | C1: CANTIDAD | D1: PRODUCTO | E1: COMENTARIOS (SI ES REGALO, HORA DE ENTREGA ESPECIFICA, MARCADO X ALGO) | F1: METODO DE PAGO | G1: DOMICILIO | H1: DOMICILIARIO | I1: DOMICILIO COBRO A CLIENTE | J1: PRECIO TOTAL | K1: PAGO DOMICILIO REAL | L1: FACTURA ELECTRONICA | M1: ENTREGADO | N1: TRASLADADO
A2: AMBIENTE LIVING | B2: 46024 | C2: 1 | D2: GRANDE OG | E2: MARCAD X10 | G2: SI | H2: INDRIVE | I2: 8000 | J2: =IF(A2="RAPPI",(VLOOKUP(TRIM(D2), CATALOGO!F:G, 2, FALSE) * C2)+I2,IFERROR(IF(COUNTIF('RESTAURANTESDESCUENTOS 2026'!A:A,TRIM(A2))>0,((VLOOKUP(TRIM(D2), CATALOGO!A:B, 2, FALSE) * C2)*(1-VALUE(SUBSTITUTE(VLOOKUP(TRIM(A2),'RESTAURANTESDESCUENTOS 2026'!A:B,2,FALSE),"%",""))/100)+I2),(VLOOKUP(TRIM(D2), CATALOGO!A:B, 2, FALSE) * C2+I2)),"")) -> 105125 | K2: 10000 | L2: SI | M2: SI
A3: AZUL SELVA | B3: 46024 | C3: 1 | D3: GRANDE OG | E3: MARCADA X12 | G3: SI | H3: INDRIVE | I3: 0 | J3: =IF(A3="RAPPI",(VLOOKUP(TRIM(D3), CATALOGO!F:G, 2, FALSE) * C3)+I3,IFERROR(IF(COUNTIF('RESTAURANTESDESCUENTOS 2026'!A:A,TRIM(A3))>0,((VLOOKUP(TRIM(D3), CATALOGO!A:B, 2, FALSE) * C3)*(1-VALUE(SUBSTITUTE(VLOOKUP(TRIM(A3),'RESTAURANTESDESCUENTOS 2026'!A:B,2,FALSE),"%",""))/100)+I3),(VLOOKUP(TRIM(D3), CATALOGO!A:B, 2, FALSE) * C3+I3)),"")) -> 112500 | K3: 10000 | L3: SI | M3: SI
A4: REGINA ROJAS | B4: 46024 | C4: 1 | D4: MEDIANA NAVIDAD | E4: NAVIDAD | G4: SI | H4: INDRIVE | I4: 14000 | J4: =IF(A4="RAPPI",(VLOOKUP(TRIM(D4), CATALOGO!F:G, 2, FALSE) * C4)+I4,IFERROR(IF(COUNTIF('RESTAURANTESDESCUENTOS 2026'!A:A,TRIM(A4))>0,((VLOOKUP(TRIM(D4), CATALOGO!A:B, 2, FALSE) * C4)*(1-VALUE(SUBSTITUTE(VLOOKUP(TRIM(A4),'RESTAURANTESDESCUENTOS 2026'!A:B,2,FALSE),"%",""))/100)+I4),(VLOOKUP(TRIM(D4), CATALOGO!A:B, 2, FALSE) * C4+I4)),"")) -> 137000 | K4: 14000 | M4: SI
A5: MIGUEL ANGEL VERA | B5: 46024 | C5: 1 | D5: MEDIANA OG | G5: SI | H5: INDRIVE | I5: 12000 | J5: =IF(A5="RAPPI",(VLOOKUP(TRIM(D5), CATALOGO!F:G, 2, FALSE) * C5)+I5,IFERROR(IF(COUNTIF('RESTAURANTESDESCUENTOS 2026'!A:A,TRIM(A5))>0,((VLOOKUP(TRIM(D5), CATALOGO!A:B, 2, FALSE) * C5)*(1-VALUE(SUBSTITUTE(VLOOKUP(TRIM(A5),'RESTAURANTESDESCUENTOS 2026'!A:B,2,FALSE),"%",""))/100)+I5),(VLOOKUP(TRIM(D5), CATALOGO!A:B, 2, FALSE) * C5+I5)),"")) -> 127000 | K5: 12000 | M5: SI
A6: CASA FLORA | B6: 46024 | C6: 1 | D6: GRANDE OG | E6: MARCADA X12 / YA ESTA DESPACHADO | G6: SI | H6: INDRIVE | I6: 0 | J6: =IF(A6="RAPPI",(VLOOKUP(TRIM(D6), CATALOGO!F:G, 2, FALSE) * C6)+I6,IFERROR(IF(COUNTIF('RESTAURANTESDESCUENTOS 2026'!A:A,TRIM(A6))>0,((VLOOKUP(TRIM(D6), CATALOGO!A:B, 2, FALSE) * C6)*(1-VALUE(SUBSTITUTE(VLOOKUP(TRIM(A6),'RESTAURANTESDESCUENTOS 2026'!A:B,2,FALSE),"%",""))/100)+I6),(VLOOKUP(TRIM(D6), CATALOGO!A:B, 2, FALSE) * C6+I6)),"")) -> 105000 | K6: 0 | L6: SI | M6: SI
A7: BARBARO RIONEGRO | B7: 46024 | C7: 3 | D7: MEDIANA OG | E7: RIONEGRO / MARCADA X10 | G7: SI | H7: INDRIVE | I7: 0 | J7: =IF(A7="RAPPI",(VLOOKUP(TRIM(D7), CATALOGO!F:G, 2, FALSE) * C7)+I7,IFERROR(IF(COUNTIF('RESTAURANTESDESCUENTOS 2026'!A:A,TRIM(A7))>0,((VLOOKUP(TRIM(D7), CATALOGO!A:B, 2, FALSE) * C7)*(1-VALUE(SUBSTITUTE(VLOOKUP(TRIM(A7),'RESTAURANTESDESCUENTOS 2026'!A:B,2,FALSE),"%",""))/100)+I7),(VLOOKUP(TRIM(D7), CATALOGO!A:B, 2, FALSE) * C7+I7)),"")) -> 258750 | K7: 0 | L7: SI | M7: SI
A8: CAMILO ALVAREZ | B8: 46024 | C8: 1 | D8: GRANDE VAINILLA | G8: NO | J8: =IF(A8="RAPPI",(VLOOKUP(TRIM(D8), CATALOGO!F:G, 2, FALSE) * C8)+I8,IFERROR(IF(COUNTIF('RESTAURANTESDESCUENTOS 2026'!A:A,TRIM(A8))>0,((VLOOKUP(TRIM(D8), CATALOGO!A:B, 2, FALSE) * C8)*(1-VALUE(SUBSTITUTE(VLOOKUP(TRIM(A8),'RESTAURANTESDESCUENTOS 2026'!A:B,2,FALSE),"%",""))/100)+I8),(VLOOKUP(TRIM(D8), CATALOGO!A:B, 2, FALSE) * C8+I8)),"")) -> 163000 | M8: SI
A9: LA ABUELA NITA | B9: 46024 | C9: 2 | D9: GRANDE OG | E9: MARCADA X12 | G9: SI | H9: INDRIVE | I9: 0 | J9: =IF(A9="RAPPI",(VLOOKUP(TRIM(D9), CATALOGO!F:G, 2, FALSE) * C9)+I9,IFERROR(IF(COUNTIF('RESTAURANTESDESCUENTOS 2026'!A:A,TRIM(A9))>0,((VLOOKUP(TRIM(D9), CATALOGO!A:B, 2, FALSE) * C9)*(1-VALUE(SUBSTITUTE(VLOOKUP(TRIM(A9),'RESTAURANTESDESCUENTOS 2026'!A:B,2,FALSE),"%",""))/100)+I9),(VLOOKUP(TRIM(D9), CATALOGO!A:B, 2, FALSE) * C9+I9)),"")) -> 225000 | K9: 0 | L9: SI | M9: SI
A10: PDV | B10: 46024 | C10: 6 | D10: MINI OG | G10: SI | H10: INDRIVE | I10: 0 | J10: 0 | K10: 170000 | M10: SI
A11: CESAR JIMENEZ | B11: 46024 | C11: 1 | D11: PORCION OG | G11: SI | H11: INDRIVE | I11: 10000 | J11: =IF(A11="RAPPI",(VLOOKUP(TRIM(D11), CATALOGO!F:G, 2, FALSE) * C11)+I11,IFERROR(IF(COUNTIF('RESTAURANTESDESCUENTOS 2026'!A:A,TRIM(A11))>0,((VLOOKUP(TRIM(D11), CATALOGO!A:B, 2, FALSE) * C11)*(1-VALUE(SUBSTITUTE(VLOOKUP(TRIM(A11),'RESTAURANTESDESCUENTOS 2026'!A:B,2,FALSE),"%",""))/100)+I11),(VLOOKUP(TRIM(D11), CATALOGO!A:B, 2, FALSE) * C11+I11)),"")) -> 28000 | K11: 10000 | M11: SI
A12: ANA MARIA OROZCO | B12: 46024 | C12: 1 | D12: MEDIANA OG | G12: SI | H12: INDRIVE | I12: 10000 | J12: =IF(A12="RAPPI",(VLOOKUP(TRIM(D12), CATALOGO!F:G, 2, FALSE) * C12)+I12,IFERROR(IF(COUNTIF('RESTAURANTESDESCUENTOS 2026'!A:A,TRIM(A12))>0,((VLOOKUP(TRIM(D12), CATALOGO!A:B, 2, FALSE) * C12)*(1-VALUE(SUBSTITUTE(VLOOKUP(TRIM(A12),'RESTAURANTESDESCUENTOS 2026'!A:B,2,FALSE),"%",""))/100)+I12),(VLOOKUP(TRIM(D12), CATALOGO!A:B, 2, FALSE) * C12+I12)),"")) -> 125000 | K12: 10000 | M12: SI
A13: LAURA HURTADO | B13: 46024 | C13: 1 | D13: MINI OG + AREQUIPE | G13: SI | H13: INDRIVE | I13: 13000 | J13: =IF(A13="RAPPI",(VLOOKUP(TRIM(D13), CATALOGO!F:G, 2, FALSE) * C13)+I13,IFERROR(IF(COUNTIF('RESTAURANTESDESCUENTOS 2026'!A:A,TRIM(A13))>0,((VLOOKUP(TRIM(D13), CATALOGO!A:B, 2, FALSE) * C13)*(1-VALUE(SUBSTITUTE(VLOOKUP(TRIM(A13),'RESTAURANTESDESCUENTOS 2026'!A:B,2,FALSE),"%",""))/100)+I13),(VLOOKUP(TRIM(D13), CATALOGO!A:B, 2, FALSE) * C13+I13)),"")) -> 66000 | K13: 13000 | M13: SI
A14: PDV | B14: 46024 | C14: 3 | D14: GRANDE OG | E14: MARCADA X12 | G14: SI | H14: INDRIVE | I14: 0 | J14: 0 | K14: 0 | M14: SI
A15: PDV | B15: 46024 | C15: 6 | D15: MEDIANA OG | G15: SI | H15: INDRIVE | I15: 0 | J15: 0 | K15: 0 | M15: SI
A16: CESAR JIMENEZ | B16: 46024 | C16: 1 | D16: PORCION OG + FRUTOS ROJOS | G16: SI | H16: INDRIVE | I16: 0 | J16: =IF(A16="RAPPI",(VLOOKUP(TRIM(D16), CATALOGO!F:G, 2, FALSE) * C16)+I16,IFERROR(IF(COUNTIF('RESTAURANTESDESCUENTOS 2026'!A:A,TRIM(A16))>0,((VLOOKUP(TRIM(D16), CATALOGO!A:B, 2, FALSE) * C16)*(1-VALUE(SUBSTITUTE(VLOOKUP(TRIM(A16),'RESTAURANTESDESCUENTOS 2026'!A:B,2,FALSE),"%",""))/100)+I16),(VLOOKUP(TRIM(D16), CATALOGO!A:B, 2, FALSE) * C16+I16)),"")) -> 22000 | K16: 0 | M16: SI
A17: RAPPI | B17: 46024 | C17: 1 | D17: GRANDE NAVIDAD | E17: 7468 | G17: SI | H17: RAPPI | J17: =IF(A17="RAPPI",(VLOOKUP(TRIM(D17), CATALOGO!F:G, 2, FALSE) * C17)+I17,IFERROR(IF(COUNTIF('RESTAURANTESDESCUENTOS 2026'!A:A,TRIM(A17))>0,((VLOOKUP(TRIM(D17), CATALOGO!A:B, 2, FALSE) * C17)*(1-VALUE(SUBSTITUTE(VLOOKUP(TRIM(A17),'RESTAURANTESDESCUENTOS 2026'!A:B,2,FALSE),"%",""))/100)+I17),(VLOOKUP(TRIM(D17), CATALOGO!A:B, 2, FALSE) * C17+I17)),"")) -> 163000 | M17: SI
A18: RAPPI | B18: 46024 | C18: 1 | D18: MINI NAVIDAD | E18: 340 | G18: SI | H18: RAPPI | J18: =IF(A18="RAPPI",(VLOOKUP(TRIM(D18), CATALOGO!F:G, 2, FALSE) * C18)+I18,IFERROR(IF(COUNTIF('RESTAURANTESDESCUENTOS 2026'!A:A,TRIM(A18))>0,((VLOOKUP(TRIM(D18), CATALOGO!A:B, 2, FALSE) * C18)*(1-VALUE(SUBSTITUTE(VLOOKUP(TRIM(A18),'RESTAURANTESDESCUENTOS 2026'!A:B,2,FALSE),"%",""))/100)+I18),(VLOOKUP(TRIM(D18), CATALOGO!A:B, 2, FALSE) * C18+I18)),"")) -> 53000 | M18: SI
A19: RAPPI | B19: 46024 | C19: 1 | D19: PORCION OG + NUTELLA | E19: 635 | G19: SI | H19: RAPPI | J19: =IF(A19="RAPPI",(VLOOKUP(TRIM(D19), CATALOGO!F:G, 2, FALSE) * C19)+I19,IFERROR(IF(COUNTIF('RESTAURANTESDESCUENTOS 2026'!A:A,TRIM(A19))>0,((VLOOKUP(TRIM(D19), CATALOGO!A:B, 2, FALSE) * C19)*(1-VALUE(SUBSTITUTE(VLOOKUP(TRIM(A19),'RESTAURANTESDESCUENTOS 2026'!A:B,2,FALSE),"%",""))/100)+I19),(VLOOKUP(TRIM(D19), CATALOGO!A:B, 2, FALSE) * C19+I19)),"")) -> 22000 | M19: SI
A20: RAPPI | B20: 46024 | C20: 1 | D20: PORCION OG + FRUTOS ROJOS | E20: 7333 | G20: SI | H20: RAPPI | J20: =IF(A20="RAPPI",(VLOOKUP(TRIM(D20), CATALOGO!F:G, 2, FALSE) * C20)+I20,IFERROR(IF(COUNTIF('RESTAURANTESDESCUENTOS 2026'!A:A,TRIM(A20))>0,((VLOOKUP(TRIM(D20), CATALOGO!A:B, 2, FALSE) * C20)*(1-VALUE(SUBSTITUTE(VLOOKUP(TRIM(A20),'RESTAURANTESDESCUENTOS 2026'!A:B,2,FALSE),"%",""))/100)+I20),(VLOOKUP(TRIM(D20), CATALOGO!A:B, 2, FALSE) * C20+I20)),"")) -> 22000 | M20: SI
A21: VENTA EN LOCAL | B21: 46024 | C21: 1 | D21: MINI NAVIDAD | E21: PAGO EN EFECTIVO | G21: NO | J21: =IF(A21="RAPPI",(VLOOKUP(TRIM(D21), CATALOGO!F:G, 2, FALSE) * C21)+I21,IFERROR(IF(COUNTIF('RESTAURANTESDESCUENTOS 2026'!A:A,TRIM(A21))>0,((VLOOKUP(TRIM(D21), CATALOGO!A:B, 2, FALSE) * C21)*(1-VALUE(SUBSTITUTE(VLOOKUP(TRIM(A21),'RESTAURANTESDESCUENTOS 2026'!A:B,2,FALSE),"%",""))/100)+I21),(VLOOKUP(TRIM(D21), CATALOGO!A:B, 2, FALSE) * C21+I21)),"")) -> 53000 | M21: SI
A22: VENTA EN LOCAL | B22: 46024 | C22: 1 | D22: MEDIANA OG | E22: PAGO EN TRANSFERENCIA | G22: NO | J22: =IF(A22="RAPPI",(VLOOKUP(TRIM(D22), CATALOGO!F:G, 2, FALSE) * C22)+I22,IFERROR(IF(COUNTIF('RESTAURANTESDESCUENTOS 2026'!A:A,TRIM(A22))>0,((VLOOKUP(TRIM(D22), CATALOGO!A:B, 2, FALSE) * C22)*(1-VALUE(SUBSTITUTE(VLOOKUP(TRIM(A22),'RESTAURANTESDESCUENTOS 2026'!A:B,2,FALSE),"%",""))/100)+I22),(VLOOKUP(TRIM(D22), CATALOGO!A:B, 2, FALSE) * C22+I22)),"")) -> 115000 | M22: SI
A23: VENTA EN LOCAL | B23: 46024 | C23: 1 | D23: PORCION OG | E23: PAGO EN TRANSFERENCIA | G23: NO | J23: =IF(A23="RAPPI",(VLOOKUP(TRIM(D23), CATALOGO!F:G, 2, FALSE) * C23)+I23,IFERROR(IF(COUNTIF('RESTAURANTESDESCUENTOS 2026'!A:A,TRIM(A23))>0,((VLOOKUP(TRIM(D23), CATALOGO!A:B, 2, FALSE) * C23)*(1-VALUE(SUBSTITUTE(VLOOKUP(TRIM(A23),'RESTAURANTESDESCUENTOS 2026'!A:B,2,FALSE),"%",""))/100)+I23),(VLOOKUP(TRIM(D23), CATALOGO!A:B, 2, FALSE) * C23+I23)),"")) -> 18000 | M23: SI
A24: ENTRECOTE BY CATA INDIANA | B24: 46025 | C24: 1 | D24: GRANDE OG | E24: INDIANA / MARCADA X10 | G24: SI | H24: INDRIVE | I24: 15000 | J24: =IF(A24="RAPPI",(VLOOKUP(TRIM(D24), CATALOGO!F:G, 2, FALSE) * C24)+I24,IFERROR(IF(COUNTIF('RESTAURANTESDESCUENTOS 2026'!A:A,TRIM(A24))>0,((VLOOKUP(TRIM(D24), CATALOGO!A:B, 2, FALSE) * C24)*(1-VALUE(SUBSTITUTE(VLOOKUP(TRIM(A24),'RESTAURANTESDESCUENTOS 2026'!A:B,2,FALSE),"%",""))/100)+I24),(VLOOKUP(TRIM(D24), CATALOGO!A:B, 2, FALSE) * C24+I24)),"")) -> 127500 | K24: 15000 | L24: SI | M24: SI
A25: LONDRES COCINA | B25: 46025 | C25: 2 | D25: GRANDE OG | E25: MARCADA X10 | G25: SI | H25: INDRIVE | I25: 10000 | J25: =IF(A25="RAPPI",(VLOOKUP(TRIM(D25), CATALOGO!F:G, 2, FALSE) * C25)+I25,IFERROR(IF(COUNTIF('RESTAURANTESDESCUENTOS 2026'!A:A,TRIM(A25))>0,((VLOOKUP(TRIM(D25), CATALOGO!A:B, 2, FALSE) * C25)*(1-VALUE(SUBSTITUTE(VLOOKUP(TRIM(A25),'RESTAURANTESDESCUENTOS 2026'!A:B,2,FALSE),"%",""))/100)+I25),(VLOOKUP(TRIM(D25), CATALOGO!A:B, 2, FALSE) * C25+I25)),"")) -> 310000 | K25: 14000 | L25: SI | M25: SI
A26: ENTRECOTE BY CATA INTERPLAZA | B26: 46025 | C26: 1 | D26: GRANDE OG | E26: INTERPLAZA / MARCADA X10 | G26: SI | H26: INDRIVE | I26: 10000 | J26: =IF(A26="RAPPI",(VLOOKUP(TRIM(D26), CATALOGO!F:G, 2, FALSE) * C26)+I26,IFERROR(IF(COUNTIF('RESTAURANTESDESCUENTOS 2026'!A:A,TRIM(A26))>0,((VLOOKUP(TRIM(D26), CATALOGO!A:B, 2, FALSE) * C26)*(1-VALUE(SUBSTITUTE(VLOOKUP(TRIM(A26),'RESTAURANTESDESCUENTOS 2026'!A:B,2,FALSE),"%",""))/100)+I26),(VLOOKUP(TRIM(D26), CATALOGO!A:B, 2, FALSE) * C26+I26)),"")) -> 122500 | K26: 10000 | L26: SI | M26: SI
A27: CASA DE NADIE | B27: 46025 | C27: 3 | D27: GRANDE OG | E27: MARCADA X12 | G27: SI | H27: INDRIVE | I27: 10000 | J27: =IF(A27="RAPPI",(VLOOKUP(TRIM(D27), CATALOGO!F:G, 2, FALSE) * C27)+I27,IFERROR(IF(COUNTIF('RESTAURANTESDESCUENTOS 2026'!A:A,TRIM(A27))>0,((VLOOKUP(TRIM(D27), CATALOGO!A:B, 2, FALSE) * C27)*(1-VALUE(SUBSTITUTE(VLOOKUP(TRIM(A27),'RESTAURANTESDESCUENTOS 2026'!A:B,2,FALSE),"%",""))/100)+I27),(VLOOKUP(TRIM(D27), CATALOGO!A:B, 2, FALSE) * C27+I27)),"")) -> 347500 | K27: 10000 | L27: SI | M27: SI
A28: AMMAZZA LAURELES | B28: 46025 | C28: 1 | D28: MEDIANA OG | E28: LAURELES / MARCADA X10 | G28: SI | H28: INDRIVE | I28: 0 | J28: =IF(A28="RAPPI",(VLOOKUP(TRIM(D28), CATALOGO!F:G, 2, FALSE) * C28)+I28,IFERROR(IF(COUNTIF('RESTAURANTESDESCUENTOS 2026'!A:A,TRIM(A28))>0,((VLOOKUP(TRIM(D28), CATALOGO!A:B, 2, FALSE) * C28)*(1-VALUE(SUBSTITUTE(VLOOKUP(TRIM(A28),'RESTAURANTESDESCUENTOS 2026'!A:B,2,FALSE),"%",""))/100)+I28),(VLOOKUP(TRIM(D28), CATALOGO!A:B, 2, FALSE) * C28+I28)),"")) -> 86250 | K28: 13000 | L28: SI | M28: SI
A29: PDV | B29: 46025 | C29: 10 | D29: GRANDE OG | E29: MARCADA X12 | G29: SI | H29: DOMICILIARIO CARLOS | I29: 0 | J29: 0 | K29: 55000 | M29: SI
A30: ESTEFANIA CARDONA | B30: 46025 | C30: 1 | D30: MINI NAVIDAD | G30: SI | H30: INDRIVE | I30: 12000 | J30: =IF(A30="RAPPI",(VLOOKUP(TRIM(D30), CATALOGO!F:G, 2, FALSE) * C30)+I30,IFERROR(IF(COUNTIF('RESTAURANTESDESCUENTOS 2026'!A:A,TRIM(A30))>0,((VLOOKUP(TRIM(D30), CATALOGO!A:B, 2, FALSE) * C30)*(1-VALUE(SUBSTITUTE(VLOOKUP(TRIM(A30),'RESTAURANTESDESCUENTOS 2026'!A:B,2,FALSE),"%",""))/100)+I30),(VLOOKUP(TRIM(D30), CATALOGO!A:B, 2, FALSE) * C30+I30)),"")) -> 65000 | K30: 12000 | M30: SI
A31: VIVIANA GIRALDO | B31: 46025 | C31: 1 | D31: MEDIANA NAVIDAD | G31: SI | H31: INDRIVE | I31: 10000 | J31: =IF(A31="RAPPI",(VLOOKUP(TRIM(D31), CATALOGO!F:G, 2, FALSE) * C31)+I31,IFERROR(IF(COUNTIF('RESTAURANTESDESCUENTOS 2026'!A:A,TRIM(A31))>0,((VLOOKUP(TRIM(D31), CATALOGO!A:B, 2, FALSE) * C31)*(1-VALUE(SUBSTITUTE(VLOOKUP(TRIM(A31),'RESTAURANTESDESCUENTOS 2026'!A:B,2,FALSE),"%",""))/100)+I31),(VLOOKUP(TRIM(D31), CATALOGO!A:B, 2, FALSE) * C31+I31)),"")) -> 133000 | K31: 10000 | M31: SI
A32: NATALIA MARTINEZ | B32: 46025 | C32: 1 | D32: MEDIANA OG + NUTELLA | E32: NAVIDAD | G32: NO | J32: =IF(A32="RAPPI",(VLOOKUP(TRIM(D32), CATALOGO!F:G, 2, FALSE) * C32)+I32,IFERROR(IF(COUNTIF('RESTAURANTESDESCUENTOS 2026'!A:A,TRIM(A32))>0,((VLOOKUP(TRIM(D32), CATALOGO!A:B, 2, FALSE) * C32)*(1-VALUE(SUBSTITUTE(VLOOKUP(TRIM(A32),'RESTAURANTESDESCUENTOS 2026'!A:B,2,FALSE),"%",""))/100)+I32),(VLOOKUP(TRIM(D32), CATALOGO!A:B, 2, FALSE) * C32+I32)),"")) -> 123000 | M32: SI
A33: PDV | B33: 46025 | C33: 5 | D33: MINI OG | G33: SI | H33: DOMICILIARIO CARLOS | I33: 0 | J33: 0 | K33: 0 | M33: SI
A34: VENTA EN LOCAL | B34: 46025 | C34: 1 | D34: MINI OG + CREMA DE MILO | E34: PAGO EN EFECTIVO | G34: NO | J34: =IF(A34="RAPPI",(VLOOKUP(TRIM(D34), CATALOGO!F:G, 2, FALSE) * C34)+I34,IFERROR(IF(COUNTIF('RESTAURANTESDESCUENTOS 2026'!A:A,TRIM(A34))>0,((VLOOKUP(TRIM(D34), CATALOGO!A:B, 2, FALSE) * C34)*(1-VALUE(SUBSTITUTE(VLOOKUP(TRIM(A34),'RESTAURANTESDESCUENTOS 2026'!A:B,2,FALSE),"%",""))/100)+I34),(VLOOKUP(TRIM(D34), CATALOGO!A:B, 2, FALSE) * C34+I34)),"")) -> 53000 | M34: SI
A35: RAPPI | B35: 46025 | C35: 1 | D35: BITES | E35: 2071 | G35: SI | H35: RAPPI | J35: =IF(A35="RAPPI",(VLOOKUP(TRIM(D35), CATALOGO!F:G, 2, FALSE) * C35)+I35,IFERROR(IF(COUNTIF('RESTAURANTESDESCUENTOS 2026'!A:A,TRIM(A35))>0,((VLOOKUP(TRIM(D35), CATALOGO!A:B, 2, FALSE) * C35)*(1-VALUE(SUBSTITUTE(VLOOKUP(TRIM(A35),'RESTAURANTESDESCUENTOS 2026'!A:B,2,FALSE),"%",""))/100)+I35),(VLOOKUP(TRIM(D35), CATALOGO!A:B, 2, FALSE) * C35+I35)),"")) -> #N/A | M35: SI
A36: RAPPI | B36: 46025 | C36: 4 | D36: AREQUIPE | E36: 2071 | G36: SI | H36: RAPPI | J36: 0 | M36: SI
A37: VENTA EN LOCAL | B37: 46025 | C37: 2 | D37: PORCION OG | E37: PAGO EN EFECTIVO | G37: NO | J37: =IF(A37="RAPPI",(VLOOKUP(TRIM(D37), CATALOGO!F:G, 2, FALSE) * C37)+I37,IFERROR(IF(COUNTIF('RESTAURANTESDESCUENTOS 2026'!A:A,TRIM(A37))>0,((VLOOKUP(TRIM(D37), CATALOGO!A:B, 2, FALSE) * C37)*(1-VALUE(SUBSTITUTE(VLOOKUP(TRIM(A37),'RESTAURANTESDESCUENTOS 2026'!A:B,2,FALSE),"%",""))/100)+I37),(VLOOKUP(TRIM(D37), CATALOGO!A:B, 2, FALSE) * C37+I37)),"")) -> 36000 | M37: SI
A38: VENTA EN LOCAL | B38: 46025 | C38: 2 | D38: CARAMELO SALADO | E38: PAGO EN EFECTIVO | G38: NO | J38: 8000 | M38: SI
A39: VENTA EN LOCAL | B39: 46025 | C39: 1 | D39: MEDIANA OG | E39: PAGO EN TRANSFERENCIA | G39: NO | J39: =IF(A39="RAPPI",(VLOOKUP(TRIM(D39), CATALOGO!F:G, 2, FALSE) * C39)+I39,IFERROR(IF(COUNTIF('RESTAURANTESDESCUENTOS 2026'!A:A,TRIM(A39))>0,((VLOOKUP(TRIM(D39), CATALOGO!A:B, 2, FALSE) * C39)*(1-VALUE(SUBSTITUTE(VLOOKUP(TRIM(A39),'RESTAURANTESDESCUENTOS 2026'!A:B,2,FALSE),"%",""))/100)+I39),(VLOOKUP(TRIM(D39), CATALOGO!A:B, 2, FALSE) * C39+I39)),"")) -> 115000 | M39: SI
A40: VENTA EN LOCAL | B40: 46025 | C40: 1 | D40: MEDIANA NAVIDAD | E40: PAGO EN EFECTIVO | G40: NO | J40: =IF(A40="RAPPI",(VLOOKUP(TRIM(D40), CATALOGO!F:G, 2, FALSE) * C40)+I40,IFERROR(IF(COUNTIF('RESTAURANTESDESCUENTOS 2026'!A:A,TRIM(A40))>0,((VLOOKUP(TRIM(D40), CATALOGO!A:B, 2, FALSE) * C40)*(1-VALUE(SUBSTITUTE(VLOOKUP(TRIM(A40),'RESTAURANTESDESCUENTOS 2026'!A:B,2,FALSE),"%",""))/100)+I40),(VLOOKUP(TRIM(D40), CATALOGO!A:B, 2, FALSE) * C40+I40)),"")) -> 123000 | M40: SI
...

Sheet HOY

Sheet MAÑANA

Sheet CATALOGO
A1: NORMAL | F1: RAPPI | K1: CATALOGO | P1: CATALOGO RESTAURANTES | X1: ACTIVO
A2: PORCION OG | B2: 18000 | F2: PORCION OG | G2: 18000 | K2: PT01 | L2: BITES X4 OG | M2: =VLOOKUP(L2,$A$2:$B$52,2,FALSE) -> 37000 | P2: C16 | Q2: GRANDE ORIGINAL - R | R2: =VLOOKUP(Q2,$A$2:$B$52,2,FALSE) -> #N/A | X2: PENDIENTE
A3: MINI OG | B3: 50000 | F3: MINI OG | G3: 50000 | K3: Dom01 | L3: DOMICILIO | M3: =VLOOKUP(L3,$A$2:$B$52,2,FALSE) -> #N/A | P3: C18 | Q3: MEDIANA ORIGINAL - R | R3: =VLOOKUP(Q3,$A$2:$B$52,2,FALSE) -> #N/A | X3: NO
A4: MEDIANA OG | B4: 115000 | F4: MEDIANA OG | G4: 115000 | K4: PT30 | L4: FRUTOS ROJOS | M4: =VLOOKUP(L4,$A$2:$B$52,2,FALSE) | Q4: VARIEDAD
A5: GRANDE OG | B5: 150000 | F5: GRANDE OG | G5: 150000 | K5: PT59 | L5: GRANDE LIMON | M5: =VLOOKUP(L5,$A$2:$B$52,2,FALSE) -> 154000 | Q5: MINI ORIGINAL - VELEZ CAFE | X5: OK
A6: PORCION OG + AREQUIPE | B6: 22000 | F6: PORCION OG + AREQUIPE | G6: 22000 | K6: PT02 | L6: GRANDE LOTUS | M6: =VLOOKUP(L6,$A$2:$B$52,2,FALSE) -> 189000 | Q6: MINI PISTACHO - VELEZ CAFE
A7: MINI OG + AREQUIPE | B7: 53000 | F7: MINI OG + AREQUIPE | G7: 53000 | K7: PT55 | L7: GRANDE MILO | M7: =VLOOKUP(L7,$A$2:$B$52,2,FALSE) -> 160000 | Q7: MINI MILO - VELEZ CAFE
A8: MEDIANA OG + AREQUIPE | B8: 123000 | F8: MEDIANA OG + AREQUIPE | G8: 123000 | K8: PT13 | L8: GRANDE NUTELLA | M8: =VLOOKUP(L8,$A$2:$B$52,2,FALSE) -> 176000 | Q8: MEDIANA PISTACHO - R
A9: GRANDE OG + AREQUIPE | B9: 163000 | F9: GRANDE OG + AREQUIPE | G9: 163000 | K9: PT19 | L9: GRANDE OG | M9: =VLOOKUP(L9,$A$2:$B$52,2,FALSE) -> 150000
A10: PORCION OG + NUTELLA | B10: 22000 | F10: PORCION OG + NUTELLA | G10: 22000 | K10: C07 | L10: GRANDE OG + AREQUIPE | M10: =VLOOKUP(L10,$A$2:$B$52,2,FALSE) -> 163000
A11: MINI OG + NUTELLA | B11: 53000 | F11: MINI OG + NUTELLA | G11: 53000 | K11: C06 | L11: GRANDE OG + CREMA DE MILO | M11: =VLOOKUP(L11,$A$2:$B$52,2,FALSE) -> 163000
A12: MEDIANA OG + NUTELLA | B12: 123000 | F12: MEDIANA OG + NUTELLA | G12: 123000 | K12: C12 | L12: GRANDE OG + FRUTOS ROJOS | M12: =VLOOKUP(L12,$A$2:$B$52,2,FALSE) -> 163000
A13: GRANDE OG + NUTELLA | B13: 163000 | F13: GRANDE OG + NUTELLA | G13: 163000 | K13: C14 | L13: GRANDE OG + NUTELLA | M13: =VLOOKUP(L13,$A$2:$B$52,2,FALSE) -> 163000
A14: PORCION OG + CREMA DE MILO | B14: 22000 | F14: PORCION OG + CREMA DE MILO | G14: 22000 | K14: C16 | L14: GRANDE ORIGINAL - R | M14: =VLOOKUP(L14,$A$2:$B$52,2,FALSE) -> #N/A
A15: MINI OG + CREMA DE MILO | B15: 53000 | F15: MINI OG + CREMA DE MILO | G15: 53000 | K15: PT22 | L15: GRANDE PISTACHO | M15: =VLOOKUP(L15,$A$2:$B$52,2,FALSE) -> 233000
A16: MEDIANA OG + CREMA DE MILO | B16: 123000 | F16: MEDIANA OG + CREMA DE MILO | G16: 123000 | K16: PT32 | L16: GRANDE VAINILLA | M16: =VLOOKUP(L16,$A$2:$B$52,2,FALSE) -> 163000
A17: GRANDE OG + CREMA DE MILO | B17: 163000 | F17: GRANDE OG + CREMA DE MILO | G17: 163000 | K17: PT58 | L17: MEDIANA LIMON | M17: =VLOOKUP(L17,$A$2:$B$52,2,FALSE) -> 119000
A18: PORCION OG + FRUTOS ROJOS | B18: 22000 | F18: PORCION OG + FRUTOS ROJOS | G18: 22000 | K18: PT23 | L18: MEDIANA LOTUS | M18: =VLOOKUP(L18,$A$2:$B$52,2,FALSE) -> 145000
A19: MINI OG + FRUTOS ROJOS | B19: 53000 | F19: MINI OG + FRUTOS ROJOS | G19: 53000 | K19: PT56 | L19: MEDIANA MILO | M19: =VLOOKUP(L19,$A$2:$B$52,2,FALSE) -> 124000
A20: MEDIANA OG + FRUTOS ROJOS | B20: 123000 | F20: MEDIANA OG + FRUTOS ROJOS | G20: 123000 | K20: PT24 | L20: MEDIANA NUTELLA | M20: =VLOOKUP(L20,$A$2:$B$52,2,FALSE) -> 132000
... A37: PORCION MILO | B37: 22000 | F37: PORCION MILO | G37: 22000 | K37: C08 | L37: MINI OG + NUTELLA | M37: =VLOOKUP(L37,$A$2:$B$52,2,FALSE) -> 53000
A38: MINI LIMON | B38: 55000 | F38: MINI LIMON | G38: 55000
A39: MEDIANA LIMON | B39: 119000 | F39: MEDIANA LIMON | G39: 119000 | K39: PT11 | L39: MINI PISTACHO | M39: =VLOOKUP(L39,$A$2:$B$52,2,FALSE) -> 55000
A40: GRANDE LIMON | B40: 154000 | F40: GRANDE LIMON | G40: 154000 | K40: PT31 | L40: MINI VAINILLA | M40: =VLOOKUP(L40,$A$2:$B$52,2,FALSE) -> 55000
A41: BITES X4 OG | B41: 37000 | F41: BITES X4 OG | G41: 37000 | K41: PT40 | L41: PORCION GRANDE MERMELADA FRUTOS ROJOS | M41: =VLOOKUP(L41,$A$2:$B$52,2,FALSE) -> #N/A
A42: AREQUIPE | F42: AREQUIPE | K42: PT45 | L42: PORCION MEDIANA MERMELADA FRUTOS ROJOS | M42: =VLOOKUP(L42,$A$2:$B$52,2,FALSE) -> #N/A
A43: NUTELLA | F43: NUTELLA | K43: PT52 | L43: PORCION MILO | M43: =VLOOKUP(L43,$A$2:$B$52,2,FALSE) -> 22000
A44: FRUTOS ROJOS | F44: FRUTOS ROJOS | K44: PT42 | L44: PORCION MINI MERMELADA FRUTOS ROJOS | M44: =VLOOKUP(L44,$A$2:$B$52,2,FALSE) -> #N/A
A45: CREMA DE MILO | F45: CREMA DE MILO | K45: PT14 | L45: PORCION OG | M45: =VLOOKUP(L45,$A$2:$B$52,2,FALSE) -> 18000
A46: CARAMELO SALADO | F46: CARAMELO SALADO
A47: VINO | B47: 30000 | K47: C04 | L47: PORCION OG + AREQUIPE | M47: =VLOOKUP(L47,$A$2:$B$52,2,FALSE) -> 22000
A48: VELAS HBD DORADA | B48: 8000 | F48: VELAS HBD DORADA | G48: 8000 | K48: C15 | L48: PORCION OG + CREMA DE MILO | M48: =VLOOKUP(L48,$A$2:$B$52,2,FALSE) -> 22000
A49: VELAS HBD PLATEADA | B49: 8000 | F49: VELAS HBD PLATEADA | G49: 8000 | K49: C10 | L49: PORCION OG + FRUTOS ROJOS | M49: =VLOOKUP(L49,$A$2:$B$52,2,FALSE) -> 22000
A50: VELAS HBD BRONCE | B50: 8000 | F50: VELAS HBD BRONCE | G50: 8000 | K50: C09 | L50: PORCION OG + NUTELLA | M50: =VLOOKUP(L50,$A$2:$B$52,2,FALSE) -> 22000
A51: VELA PALO DORADA | B51: 4000 | F51: VELA PALO DORADA | G51: 4000 | K51: V1 | L51: VELA PALO DORADA | M51: =VLOOKUP(L51,$A$2:$B$52,2,FALSE) -> 4000
A52: VELA PALO PLATEADA | B52: 4000 | F52: VELA PALO PLATEADA | G52: 4000 | K52: V2 | L52: VELA PALO PLATEADA | M52: =VLOOKUP(L52,$A$2:$B$52,2,FALSE) -> 4000
A53: MINI NAVIDAD | B53: 53000 | F53: MINI NAVIDAD | G53: 53000 | K53: V5 | L53: VELAS HBD BRONCE | M53: =VLOOKUP(L53,$A$2:$B$52,2,FALSE) -> 8000
A54: MEDIANA NAVIDAD | B54: 123000 | F54: MEDIANA NAVIDAD | G54: 123000 | K54: V3 | L54: VELAS HBD DORADA | M54: =VLOOKUP(L54,$A$2:$B$52,2,FALSE) -> 8000
A55: GRANDE NAVIDAD | B55: 163000 | F55: GRANDE NAVIDAD | G55: 163000 | K55: V4 | L55: VELAS HBD PLATEADA | M55: =VLOOKUP(L55,$A$2:$B$52,2,FALSE) -> 8000
A56: BITES X4 LOTUS | B56: 37000 | F56: BITES X4 LOTUS | G56: 37000
...
